[2016-02-09 03:26:54] ERROR    Exception on / [GET]
Traceback (most recent call last):
  File "/usr/local/lib/python2.7/site-packages/flask/app.py", line 1817, in wsgi_app
    response = self.full_dispatch_request()
  File "/usr/local/lib/python2.7/site-packages/flask/app.py", line 1477, in full_dispatch_request
    rv = self.handle_user_exception(e)
  File "/usr/local/lib/python2.7/site-packages/flask/app.py", line 1381, in handle_user_exception
    reraise(exc_type, exc_value, tb)
  File "/usr/local/lib/python2.7/site-packages/flask/app.py", line 1475, in full_dispatch_request
    rv = self.dispatch_request()
  File "/usr/local/lib/python2.7/site-packages/flask/app.py", line 1461, in dispatch_request
    return self.view_functions[rule.endpoint](**req.view_args)
  File "PCA_tester.py", line 358, in hello
    with open('/Users/pniessen/Rosetta_Desktop/Segmentation_2-point-0/index.html', 'r') as viz_file:
IOError: [Errno 2] No such file or directory: '/Users/pniessen/Rosetta_Desktop/Segmentation_2-point-0/index.html'
[2016-02-09 03:26:58] ERROR    Exception on / [GET]
Traceback (most recent call last):
  File "/usr/local/lib/python2.7/site-packages/flask/app.py", line 1817, in wsgi_app
    response = self.full_dispatch_request()
  File "/usr/local/lib/python2.7/site-packages/flask/app.py", line 1477, in full_dispatch_request
    rv = self.handle_user_exception(e)
  File "/usr/local/lib/python2.7/site-packages/flask/app.py", line 1381, in handle_user_exception
    reraise(exc_type, exc_value, tb)
  File "/usr/local/lib/python2.7/site-packages/flask/app.py", line 1475, in full_dispatch_request
    rv = self.dispatch_request()
  File "/usr/local/lib/python2.7/site-packages/flask/app.py", line 1461, in dispatch_request
    return self.view_functions[rule.endpoint](**req.view_args)
  File "PCA_tester.py", line 358, in hello
    with open('/Users/pniessen/Rosetta_Desktop/Segmentation_2-point-0/index.html', 'r') as viz_file:
IOError: [Errno 2] No such file or directory: '/Users/pniessen/Rosetta_Desktop/Segmentation_2-point-0/index.html'
[2016-02-09 03:29:56] ERROR    Exception on / [GET]
Traceback (most recent call last):
  File "/usr/local/lib/python2.7/site-packages/flask/app.py", line 1817, in wsgi_app
    response = self.full_dispatch_request()
  File "/usr/local/lib/python2.7/site-packages/flask/app.py", line 1477, in full_dispatch_request
    rv = self.handle_user_exception(e)
  File "/usr/local/lib/python2.7/site-packages/flask/app.py", line 1381, in handle_user_exception
    reraise(exc_type, exc_value, tb)
  File "/usr/local/lib/python2.7/site-packages/flask/app.py", line 1475, in full_dispatch_request
    rv = self.dispatch_request()
  File "/usr/local/lib/python2.7/site-packages/flask/app.py", line 1461, in dispatch_request
    return self.view_functions[rule.endpoint](**req.view_args)
  File "PCA_tester.py", line 358, in hello
    with open('/Users/pniessen/Rosetta_Desktop/Segmentation_2-point-0/index.html', 'r') as viz_file:
IOError: [Errno 2] No such file or directory: '/Users/pniessen/Rosetta_Desktop/Segmentation_2-point-0/index.html'
[2016-02-09 03:29:59] ERROR    Exception on / [GET]
Traceback (most recent call last):
  File "/usr/local/lib/python2.7/site-packages/flask/app.py", line 1817, in wsgi_app
    response = self.full_dispatch_request()
  File "/usr/local/lib/python2.7/site-packages/flask/app.py", line 1477, in full_dispatch_request
    rv = self.handle_user_exception(e)
  File "/usr/local/lib/python2.7/site-packages/flask/app.py", line 1381, in handle_user_exception
    reraise(exc_type, exc_value, tb)
  File "/usr/local/lib/python2.7/site-packages/flask/app.py", line 1475, in full_dispatch_request
    rv = self.dispatch_request()
  File "/usr/local/lib/python2.7/site-packages/flask/app.py", line 1461, in dispatch_request
    return self.view_functions[rule.endpoint](**req.view_args)
  File "PCA_tester.py", line 358, in hello
    with open('/Users/pniessen/Rosetta_Desktop/Segmentation_2-point-0/index.html', 'r') as viz_file:
IOError: [Errno 2] No such file or directory: '/Users/pniessen/Rosetta_Desktop/Segmentation_2-point-0/index.html'
[2016-02-09 03:30:06] ERROR    Exception on / [GET]
Traceback (most recent call last):
  File "/usr/local/lib/python2.7/site-packages/flask/app.py", line 1817, in wsgi_app
    response = self.full_dispatch_request()
  File "/usr/local/lib/python2.7/site-packages/flask/app.py", line 1477, in full_dispatch_request
    rv = self.handle_user_exception(e)
  File "/usr/local/lib/python2.7/site-packages/flask/app.py", line 1381, in handle_user_exception
    reraise(exc_type, exc_value, tb)
  File "/usr/local/lib/python2.7/site-packages/flask/app.py", line 1475, in full_dispatch_request
    rv = self.dispatch_request()
  File "/usr/local/lib/python2.7/site-packages/flask/app.py", line 1461, in dispatch_request
    return self.view_functions[rule.endpoint](**req.view_args)
  File "PCA_tester.py", line 358, in hello
    with open('/Users/pniessen/Rosetta_Desktop/Segmentation_2-point-0/index.html', 'r') as viz_file:
IOError: [Errno 2] No such file or directory: '/Users/pniessen/Rosetta_Desktop/Segmentation_2-point-0/index.html'
[2016-02-09 03:32:36] ERROR    Exception on / [GET]
Traceback (most recent call last):
  File "/usr/local/lib/python2.7/site-packages/flask/app.py", line 1817, in wsgi_app
    response = self.full_dispatch_request()
  File "/usr/local/lib/python2.7/site-packages/flask/app.py", line 1477, in full_dispatch_request
    rv = self.handle_user_exception(e)
  File "/usr/local/lib/python2.7/site-packages/flask/app.py", line 1381, in handle_user_exception
    reraise(exc_type, exc_value, tb)
  File "/usr/local/lib/python2.7/site-packages/flask/app.py", line 1475, in full_dispatch_request
    rv = self.dispatch_request()
  File "/usr/local/lib/python2.7/site-packages/flask/app.py", line 1461, in dispatch_request
    return self.view_functions[rule.endpoint](**req.view_args)
  File "PCA_tester.py", line 358, in hello
    with open('/Users/pniessen/Rosetta_Desktop/Segmentation_2-point-0/index.html', 'r') as viz_file:
IOError: [Errno 2] No such file or directory: '/Users/pniessen/Rosetta_Desktop/Segmentation_2-point-0/index.html'
[2016-02-09 03:32:41] ERROR    Exception on / [GET]
Traceback (most recent call last):
  File "/usr/local/lib/python2.7/site-packages/flask/app.py", line 1817, in wsgi_app
    response = self.full_dispatch_request()
  File "/usr/local/lib/python2.7/site-packages/flask/app.py", line 1477, in full_dispatch_request
    rv = self.handle_user_exception(e)
  File "/usr/local/lib/python2.7/site-packages/flask/app.py", line 1381, in handle_user_exception
    reraise(exc_type, exc_value, tb)
  File "/usr/local/lib/python2.7/site-packages/flask/app.py", line 1475, in full_dispatch_request
    rv = self.dispatch_request()
  File "/usr/local/lib/python2.7/site-packages/flask/app.py", line 1461, in dispatch_request
    return self.view_functions[rule.endpoint](**req.view_args)
  File "PCA_tester.py", line 358, in hello
    with open('/Users/pniessen/Rosetta_Desktop/Segmentation_2-point-0/index.html', 'r') as viz_file:
IOError: [Errno 2] No such file or directory: '/Users/pniessen/Rosetta_Desktop/Segmentation_2-point-0/index.html'
[2016-02-09 03:32:53] ERROR    Exception on / [GET]
Traceback (most recent call last):
  File "/usr/local/lib/python2.7/site-packages/flask/app.py", line 1817, in wsgi_app
    response = self.full_dispatch_request()
  File "/usr/local/lib/python2.7/site-packages/flask/app.py", line 1477, in full_dispatch_request
    rv = self.handle_user_exception(e)
  File "/usr/local/lib/python2.7/site-packages/flask/app.py", line 1381, in handle_user_exception
    reraise(exc_type, exc_value, tb)
  File "/usr/local/lib/python2.7/site-packages/flask/app.py", line 1475, in full_dispatch_request
    rv = self.dispatch_request()
  File "/usr/local/lib/python2.7/site-packages/flask/app.py", line 1461, in dispatch_request
    return self.view_functions[rule.endpoint](**req.view_args)
  File "PCA_tester.py", line 358, in hello
    with open('/Users/pniessen/Rosetta_Desktop/Segmentation_2-point-0/index.html', 'r') as viz_file:
IOError: [Errno 2] No such file or directory: '/Users/pniessen/Rosetta_Desktop/Segmentation_2-point-0/index.html'
[2016-02-10 15:52:11] ERROR    Exception on /tracker [GET]
Traceback (most recent call last):
  File "/usr/local/lib/python2.7/site-packages/flask/app.py", line 1817, in wsgi_app
    response = self.full_dispatch_request()
  File "/usr/local/lib/python2.7/site-packages/flask/app.py", line 1477, in full_dispatch_request
    rv = self.handle_user_exception(e)
  File "/usr/local/lib/python2.7/site-packages/flask/app.py", line 1381, in handle_user_exception
    reraise(exc_type, exc_value, tb)
  File "/usr/local/lib/python2.7/site-packages/flask/app.py", line 1475, in full_dispatch_request
    rv = self.dispatch_request()
  File "/usr/local/lib/python2.7/site-packages/flask/app.py", line 1461, in dispatch_request
    return self.view_functions[rule.endpoint](**req.view_args)
  File "PCA_tester.py", line 441, in run_tracker
    if len(results_dict) == 0:
NameError: global name 'results_dict' is not defined
[2016-02-10 15:52:25] ERROR    Exception on /tracker [GET]
Traceback (most recent call last):
  File "/usr/local/lib/python2.7/site-packages/flask/app.py", line 1817, in wsgi_app
    response = self.full_dispatch_request()
  File "/usr/local/lib/python2.7/site-packages/flask/app.py", line 1477, in full_dispatch_request
    rv = self.handle_user_exception(e)
  File "/usr/local/lib/python2.7/site-packages/flask/app.py", line 1381, in handle_user_exception
    reraise(exc_type, exc_value, tb)
  File "/usr/local/lib/python2.7/site-packages/flask/app.py", line 1475, in full_dispatch_request
    rv = self.dispatch_request()
  File "/usr/local/lib/python2.7/site-packages/flask/app.py", line 1461, in dispatch_request
    return self.view_functions[rule.endpoint](**req.view_args)
  File "PCA_tester.py", line 441, in run_tracker
    if len(results_dict) == 0:
NameError: global name 'results_dict' is not defined
[2016-02-10 15:52:25] ERROR    Exception on /data [GET]
Traceback (most recent call last):
  File "/usr/local/lib/python2.7/site-packages/flask/app.py", line 1817, in wsgi_app
    response = self.full_dispatch_request()
  File "/usr/local/lib/python2.7/site-packages/flask/app.py", line 1477, in full_dispatch_request
    rv = self.handle_user_exception(e)
  File "/usr/local/lib/python2.7/site-packages/flask/app.py", line 1381, in handle_user_exception
    reraise(exc_type, exc_value, tb)
  File "/usr/local/lib/python2.7/site-packages/flask/app.py", line 1475, in full_dispatch_request
    rv = self.dispatch_request()
  File "/usr/local/lib/python2.7/site-packages/flask/app.py", line 1461, in dispatch_request
    return self.view_functions[rule.endpoint](**req.view_args)
  File "PCA_tester.py", line 410, in scorecard
    print "results_dict size: ", len(results_dict.keys())
NameError: global name 'results_dict' is not defined
[2016-02-10 15:55:22] ERROR    Exception on /tracker [GET]
Traceback (most recent call last):
  File "/usr/local/lib/python2.7/site-packages/flask/app.py", line 1817, in wsgi_app
    response = self.full_dispatch_request()
  File "/usr/local/lib/python2.7/site-packages/flask/app.py", line 1477, in full_dispatch_request
    rv = self.handle_user_exception(e)
  File "/usr/local/lib/python2.7/site-packages/flask/app.py", line 1381, in handle_user_exception
    reraise(exc_type, exc_value, tb)
  File "/usr/local/lib/python2.7/site-packages/flask/app.py", line 1475, in full_dispatch_request
    rv = self.dispatch_request()
  File "/usr/local/lib/python2.7/site-packages/flask/app.py", line 1461, in dispatch_request
    return self.view_functions[rule.endpoint](**req.view_args)
  File "PCA_tester.py", line 442, in run_tracker
    tracker_dict = OrderedDict([('001_Q#',key),('002_Q_name','n/a'),('003_Dim','n/a'), ('004_PCA', round(question_dict[key]['first_factor_value'],3)),('005_#1 Factor', question_dict[key]['first_factor']),('006_#2 Factor', question_dict[key]['second_factor']),('007_Bucket', question_dict[key]['bucket_scheme']),('008_%T(=1)', round(question_dict[key]['rebucket_shares_1']*100)),('009_%M(=2)', round(question_dict[key]['rebucket_shares_2']*100)),('010_%L(=3)', round(question_dict[key]['rebucket_shares_3']*100)), ('011_RH',round(question_dict[key]['best_rh'],2))])
UnboundLocalError: local variable 'key' referenced before assignment
[2016-02-10 16:30:07] ERROR    Exception on /tracker [GET]
Traceback (most recent call last):
  File "/usr/local/lib/python2.7/site-packages/flask/app.py", line 1817, in wsgi_app
    response = self.full_dispatch_request()
  File "/usr/local/lib/python2.7/site-packages/flask/app.py", line 1477, in full_dispatch_request
    rv = self.handle_user_exception(e)
  File "/usr/local/lib/python2.7/site-packages/flask/app.py", line 1381, in handle_user_exception
    reraise(exc_type, exc_value, tb)
  File "/usr/local/lib/python2.7/site-packages/flask/app.py", line 1475, in full_dispatch_request
    rv = self.dispatch_request()
  File "/usr/local/lib/python2.7/site-packages/flask/app.py", line 1461, in dispatch_request
    return self.view_functions[rule.endpoint](**req.view_args)
  File "PCA_tester.py", line 454, in run_tracker
    r_dict = OrderedDict(zip(r_dict_keys, question_dict[key]['bool_run_tracker']))
KeyError: '65b16fe8-a892-448a-b2da-4a6785ee696e'
[2016-02-10 16:36:10] ERROR    Exception on /tracker [GET]
Traceback (most recent call last):
  File "/usr/local/lib/python2.7/site-packages/flask/app.py", line 1817, in wsgi_app
    response = self.full_dispatch_request()
  File "/usr/local/lib/python2.7/site-packages/flask/app.py", line 1477, in full_dispatch_request
    rv = self.handle_user_exception(e)
  File "/usr/local/lib/python2.7/site-packages/flask/app.py", line 1381, in handle_user_exception
    reraise(exc_type, exc_value, tb)
  File "/usr/local/lib/python2.7/site-packages/flask/app.py", line 1475, in full_dispatch_request
    rv = self.dispatch_request()
  File "/usr/local/lib/python2.7/site-packages/flask/app.py", line 1461, in dispatch_request
    return self.view_functions[rule.endpoint](**req.view_args)
  File "PCA_tester.py", line 473, in run_tracker
    r_dict = OrderedDict(zip(r_dict_keys, question_dict[key]['bool_run_tracker']))
KeyError: 'de8118ec-b488-48a0-ad16-66348d64e806'
[2016-02-10 16:36:14] ERROR    Exception on /tracker [GET]
Traceback (most recent call last):
  File "/usr/local/lib/python2.7/site-packages/flask/app.py", line 1817, in wsgi_app
    response = self.full_dispatch_request()
  File "/usr/local/lib/python2.7/site-packages/flask/app.py", line 1477, in full_dispatch_request
    rv = self.handle_user_exception(e)
  File "/usr/local/lib/python2.7/site-packages/flask/app.py", line 1381, in handle_user_exception
    reraise(exc_type, exc_value, tb)
  File "/usr/local/lib/python2.7/site-packages/flask/app.py", line 1475, in full_dispatch_request
    rv = self.dispatch_request()
  File "/usr/local/lib/python2.7/site-packages/flask/app.py", line 1461, in dispatch_request
    return self.view_functions[rule.endpoint](**req.view_args)
  File "PCA_tester.py", line 473, in run_tracker
    r_dict = OrderedDict(zip(r_dict_keys, question_dict[key]['bool_run_tracker']))
KeyError: 'de8118ec-b488-48a0-ad16-66348d64e806'
[2016-02-10 17:34:11] ERROR    Exception on /tracker [GET]
Traceback (most recent call last):
  File "/usr/local/lib/python2.7/site-packages/flask/app.py", line 1817, in wsgi_app
    response = self.full_dispatch_request()
  File "/usr/local/lib/python2.7/site-packages/flask/app.py", line 1478, in full_dispatch_request
    response = self.make_response(rv)
  File "/usr/local/lib/python2.7/site-packages/flask/app.py", line 1566, in make_response
    raise ValueError('View function did not return a response')
ValueError: View function did not return a response
[2016-02-10 17:34:19] ERROR    Exception on /tracker [GET]
Traceback (most recent call last):
  File "/usr/local/lib/python2.7/site-packages/flask/app.py", line 1817, in wsgi_app
    response = self.full_dispatch_request()
  File "/usr/local/lib/python2.7/site-packages/flask/app.py", line 1478, in full_dispatch_request
    response = self.make_response(rv)
  File "/usr/local/lib/python2.7/site-packages/flask/app.py", line 1566, in make_response
    raise ValueError('View function did not return a response')
ValueError: View function did not return a response
[2016-02-10 17:40:32] ERROR    Exception on /tracker [GET]
Traceback (most recent call last):
  File "/usr/local/lib/python2.7/site-packages/flask/app.py", line 1817, in wsgi_app
    response = self.full_dispatch_request()
  File "/usr/local/lib/python2.7/site-packages/flask/app.py", line 1478, in full_dispatch_request
    response = self.make_response(rv)
  File "/usr/local/lib/python2.7/site-packages/flask/app.py", line 1566, in make_response
    raise ValueError('View function did not return a response')
ValueError: View function did not return a response
[2016-02-10 17:40:41] ERROR    Exception on /tracker [GET]
Traceback (most recent call last):
  File "/usr/local/lib/python2.7/site-packages/flask/app.py", line 1817, in wsgi_app
    response = self.full_dispatch_request()
  File "/usr/local/lib/python2.7/site-packages/flask/app.py", line 1478, in full_dispatch_request
    response = self.make_response(rv)
  File "/usr/local/lib/python2.7/site-packages/flask/app.py", line 1566, in make_response
    raise ValueError('View function did not return a response')
ValueError: View function did not return a response
[2016-02-11 16:13:45] ERROR    Exception on /create_tracker [GET]
Traceback (most recent call last):
  File "/usr/local/lib/python2.7/site-packages/flask/app.py", line 1817, in wsgi_app
    response = self.full_dispatch_request()
  File "/usr/local/lib/python2.7/site-packages/flask/app.py", line 1477, in full_dispatch_request
    rv = self.handle_user_exception(e)
  File "/usr/local/lib/python2.7/site-packages/flask/app.py", line 1381, in handle_user_exception
    reraise(exc_type, exc_value, tb)
  File "/usr/local/lib/python2.7/site-packages/flask/app.py", line 1475, in full_dispatch_request
    rv = self.dispatch_request()
  File "/usr/local/lib/python2.7/site-packages/flask/app.py", line 1461, in dispatch_request
    return self.view_functions[rule.endpoint](**req.view_args)
  File "PCA_tester.py", line 450, in create_run_tracker
    return flask.jsonify(tracker)
NameError: global name 'flask' is not defined
[2016-02-11 16:18:24] ERROR    Exception on /create_tracker [GET]
Traceback (most recent call last):
  File "/usr/local/lib/python2.7/site-packages/flask/app.py", line 1817, in wsgi_app
    response = self.full_dispatch_request()
  File "/usr/local/lib/python2.7/site-packages/flask/app.py", line 1477, in full_dispatch_request
    rv = self.handle_user_exception(e)
  File "/usr/local/lib/python2.7/site-packages/flask/app.py", line 1381, in handle_user_exception
    reraise(exc_type, exc_value, tb)
  File "/usr/local/lib/python2.7/site-packages/flask/app.py", line 1475, in full_dispatch_request
    rv = self.dispatch_request()
  File "/usr/local/lib/python2.7/site-packages/flask/app.py", line 1461, in dispatch_request
    return self.view_functions[rule.endpoint](**req.view_args)
  File "PCA_tester.py", line 450, in create_run_tracker
    return flask.jsonify(tracker)
NameError: global name 'flask' is not defined
[2016-02-11 16:21:32] ERROR    Exception on /create_tracker [GET]
Traceback (most recent call last):
  File "/usr/local/lib/python2.7/site-packages/flask/app.py", line 1817, in wsgi_app
    response = self.full_dispatch_request()
  File "/usr/local/lib/python2.7/site-packages/flask/app.py", line 1477, in full_dispatch_request
    rv = self.handle_user_exception(e)
  File "/usr/local/lib/python2.7/site-packages/flask/app.py", line 1381, in handle_user_exception
    reraise(exc_type, exc_value, tb)
  File "/usr/local/lib/python2.7/site-packages/flask/app.py", line 1475, in full_dispatch_request
    rv = self.dispatch_request()
  File "/usr/local/lib/python2.7/site-packages/flask/app.py", line 1461, in dispatch_request
    return self.view_functions[rule.endpoint](**req.view_args)
  File "PCA_tester.py", line 450, in create_run_tracker
    return flask.jsonify(tracker)
NameError: global name 'flask' is not defined
[2016-02-11 16:30:07] ERROR    Exception on /create_tracker [GET]
Traceback (most recent call last):
  File "/usr/local/lib/python2.7/site-packages/flask/app.py", line 1817, in wsgi_app
    response = self.full_dispatch_request()
  File "/usr/local/lib/python2.7/site-packages/flask/app.py", line 1477, in full_dispatch_request
    rv = self.handle_user_exception(e)
  File "/usr/local/lib/python2.7/site-packages/flask/app.py", line 1381, in handle_user_exception
    reraise(exc_type, exc_value, tb)
  File "/usr/local/lib/python2.7/site-packages/flask/app.py", line 1475, in full_dispatch_request
    rv = self.dispatch_request()
  File "/usr/local/lib/python2.7/site-packages/flask/app.py", line 1461, in dispatch_request
    return self.view_functions[rule.endpoint](**req.view_args)
  File "PCA_tester.py", line 450, in create_run_tracker
    return flask.jsonify(tracker)
NameError: global name 'flask' is not defined
[2016-02-11 16:30:12] ERROR    Exception on /create_tracker [GET]
Traceback (most recent call last):
  File "/usr/local/lib/python2.7/site-packages/flask/app.py", line 1817, in wsgi_app
    response = self.full_dispatch_request()
  File "/usr/local/lib/python2.7/site-packages/flask/app.py", line 1477, in full_dispatch_request
    rv = self.handle_user_exception(e)
  File "/usr/local/lib/python2.7/site-packages/flask/app.py", line 1381, in handle_user_exception
    reraise(exc_type, exc_value, tb)
  File "/usr/local/lib/python2.7/site-packages/flask/app.py", line 1475, in full_dispatch_request
    rv = self.dispatch_request()
  File "/usr/local/lib/python2.7/site-packages/flask/app.py", line 1461, in dispatch_request
    return self.view_functions[rule.endpoint](**req.view_args)
  File "PCA_tester.py", line 450, in create_run_tracker
    return flask.jsonify(tracker)
NameError: global name 'flask' is not defined
[2016-02-11 16:34:07] ERROR    Exception on /create_tracker [GET]
Traceback (most recent call last):
  File "/usr/local/lib/python2.7/site-packages/flask/app.py", line 1817, in wsgi_app
    response = self.full_dispatch_request()
  File "/usr/local/lib/python2.7/site-packages/flask/app.py", line 1477, in full_dispatch_request
    rv = self.handle_user_exception(e)
  File "/usr/local/lib/python2.7/site-packages/flask/app.py", line 1381, in handle_user_exception
    reraise(exc_type, exc_value, tb)
  File "/usr/local/lib/python2.7/site-packages/flask/app.py", line 1475, in full_dispatch_request
    rv = self.dispatch_request()
  File "/usr/local/lib/python2.7/site-packages/flask/app.py", line 1461, in dispatch_request
    return self.view_functions[rule.endpoint](**req.view_args)
  File "PCA_tester.py", line 450, in create_run_tracker
    return flask.jsonify(tracker)
NameError: global name 'flask' is not defined
[2016-02-11 16:34:25] ERROR    Exception on /tracker [GET]
Traceback (most recent call last):
  File "/usr/local/lib/python2.7/site-packages/flask/app.py", line 1817, in wsgi_app
    response = self.full_dispatch_request()
  File "/usr/local/lib/python2.7/site-packages/flask/app.py", line 1477, in full_dispatch_request
    rv = self.handle_user_exception(e)
  File "/usr/local/lib/python2.7/site-packages/flask/app.py", line 1381, in handle_user_exception
    reraise(exc_type, exc_value, tb)
  File "/usr/local/lib/python2.7/site-packages/flask/app.py", line 1475, in full_dispatch_request
    rv = self.dispatch_request()
  File "/usr/local/lib/python2.7/site-packages/flask/app.py", line 1461, in dispatch_request
    return self.view_functions[rule.endpoint](**req.view_args)
  File "PCA_tester.py", line 512, in update_run_tracker
    return flask.jsonify(tracker)
NameError: global name 'flask' is not defined
[2016-02-11 16:40:09] ERROR    Exception on /create_tracker [GET]
Traceback (most recent call last):
  File "/usr/local/lib/python2.7/site-packages/flask/app.py", line 1817, in wsgi_app
    response = self.full_dispatch_request()
  File "/usr/local/lib/python2.7/site-packages/flask/app.py", line 1477, in full_dispatch_request
    rv = self.handle_user_exception(e)
  File "/usr/local/lib/python2.7/site-packages/flask/app.py", line 1381, in handle_user_exception
    reraise(exc_type, exc_value, tb)
  File "/usr/local/lib/python2.7/site-packages/flask/app.py", line 1475, in full_dispatch_request
    rv = self.dispatch_request()
  File "/usr/local/lib/python2.7/site-packages/flask/app.py", line 1461, in dispatch_request
    return self.view_functions[rule.endpoint](**req.view_args)
  File "PCA_tester.py", line 450, in create_tracker
    return flask.jsonify(tracker)
NameError: global name 'flask' is not defined
[2016-02-11 16:45:14] ERROR    Exception on /create_tracker [GET]
Traceback (most recent call last):
  File "/usr/local/lib/python2.7/site-packages/flask/app.py", line 1817, in wsgi_app
    response = self.full_dispatch_request()
  File "/usr/local/lib/python2.7/site-packages/flask/app.py", line 1477, in full_dispatch_request
    rv = self.handle_user_exception(e)
  File "/usr/local/lib/python2.7/site-packages/flask/app.py", line 1381, in handle_user_exception
    reraise(exc_type, exc_value, tb)
  File "/usr/local/lib/python2.7/site-packages/flask/app.py", line 1475, in full_dispatch_request
    rv = self.dispatch_request()
  File "/usr/local/lib/python2.7/site-packages/flask/app.py", line 1461, in dispatch_request
    return self.view_functions[rule.endpoint](**req.view_args)
  File "PCA_tester.py", line 450, in create_tracker
    tracker_json = flask.jsonify(tracker)
NameError: global name 'flask' is not defined
[2016-02-11 17:12:03] ERROR    Exception on /tracker [GET]
Traceback (most recent call last):
  File "/usr/local/lib/python2.7/site-packages/flask/app.py", line 1817, in wsgi_app
    response = self.full_dispatch_request()
  File "/usr/local/lib/python2.7/site-packages/flask/app.py", line 1478, in full_dispatch_request
    response = self.make_response(rv)
  File "/usr/local/lib/python2.7/site-packages/flask/app.py", line 1566, in make_response
    raise ValueError('View function did not return a response')
ValueError: View function did not return a response
[2016-02-11 17:24:46] ERROR    Exception on /tracker [GET]
Traceback (most recent call last):
  File "/usr/local/lib/python2.7/site-packages/flask/app.py", line 1817, in wsgi_app
    response = self.full_dispatch_request()
  File "/usr/local/lib/python2.7/site-packages/flask/app.py", line 1478, in full_dispatch_request
    response = self.make_response(rv)
  File "/usr/local/lib/python2.7/site-packages/flask/app.py", line 1566, in make_response
    raise ValueError('View function did not return a response')
ValueError: View function did not return a response
[2016-02-11 17:25:42] ERROR    Exception on /tracker [GET]
Traceback (most recent call last):
  File "/usr/local/lib/python2.7/site-packages/flask/app.py", line 1817, in wsgi_app
    response = self.full_dispatch_request()
  File "/usr/local/lib/python2.7/site-packages/flask/app.py", line 1478, in full_dispatch_request
    response = self.make_response(rv)
  File "/usr/local/lib/python2.7/site-packages/flask/app.py", line 1566, in make_response
    raise ValueError('View function did not return a response')
ValueError: View function did not return a response
[2016-02-11 18:26:16] ERROR    Exception on /tracker [GET]
Traceback (most recent call last):
  File "/usr/local/lib/python2.7/site-packages/flask/app.py", line 1817, in wsgi_app
    response = self.full_dispatch_request()
  File "/usr/local/lib/python2.7/site-packages/flask/app.py", line 1477, in full_dispatch_request
    rv = self.handle_user_exception(e)
  File "/usr/local/lib/python2.7/site-packages/flask/app.py", line 1381, in handle_user_exception
    reraise(exc_type, exc_value, tb)
  File "/usr/local/lib/python2.7/site-packages/flask/app.py", line 1475, in full_dispatch_request
    rv = self.dispatch_request()
  File "/usr/local/lib/python2.7/site-packages/flask/app.py", line 1461, in dispatch_request
    return self.view_functions[rule.endpoint](**req.view_args)
  File "PCA_tester.py", line 504, in update_run_tracker
    r_dict = OrderedDict(zip(r_dict_keys, question_dict[key]['bool_run_tracker'][starting_run:]))
KeyError: 'edceaf0c-b938-471b-992b-73959e1e2cc9'
[2016-02-11 18:52:02] ERROR    Exception on /tracker [GET]
Traceback (most recent call last):
  File "/usr/local/lib/python2.7/site-packages/flask/app.py", line 1817, in wsgi_app
    response = self.full_dispatch_request()
  File "/usr/local/lib/python2.7/site-packages/flask/app.py", line 1478, in full_dispatch_request
    response = self.make_response(rv)
  File "/usr/local/lib/python2.7/site-packages/flask/app.py", line 1566, in make_response
    raise ValueError('View function did not return a response')
ValueError: View function did not return a response
[2016-02-11 19:01:55] ERROR    Exception on /tracker [GET]
Traceback (most recent call last):
  File "/usr/local/lib/python2.7/site-packages/flask/app.py", line 1817, in wsgi_app
    response = self.full_dispatch_request()
  File "/usr/local/lib/python2.7/site-packages/flask/app.py", line 1478, in full_dispatch_request
    response = self.make_response(rv)
  File "/usr/local/lib/python2.7/site-packages/flask/app.py", line 1566, in make_response
    raise ValueError('View function did not return a response')
ValueError: View function did not return a response
[2016-02-11 19:46:08] ERROR    Exception on /tracker [GET]
Traceback (most recent call last):
  File "/usr/local/lib/python2.7/site-packages/flask/app.py", line 1817, in wsgi_app
    response = self.full_dispatch_request()
  File "/usr/local/lib/python2.7/site-packages/flask/app.py", line 1478, in full_dispatch_request
    response = self.make_response(rv)
  File "/usr/local/lib/python2.7/site-packages/flask/app.py", line 1566, in make_response
    raise ValueError('View function did not return a response')
ValueError: View function did not return a response
[2016-02-11 20:35:02] ERROR    Exception on /tracker [GET]
Traceback (most recent call last):
  File "/usr/local/lib/python2.7/site-packages/flask/app.py", line 1817, in wsgi_app
    response = self.full_dispatch_request()
  File "/usr/local/lib/python2.7/site-packages/flask/app.py", line 1478, in full_dispatch_request
    response = self.make_response(rv)
  File "/usr/local/lib/python2.7/site-packages/flask/app.py", line 1566, in make_response
    raise ValueError('View function did not return a response')
ValueError: View function did not return a response
[2016-02-11 23:20:27] ERROR    Exception on /tracker [GET]
Traceback (most recent call last):
  File "/usr/local/lib/python2.7/site-packages/flask/app.py", line 1817, in wsgi_app
    response = self.full_dispatch_request()
  File "/usr/local/lib/python2.7/site-packages/flask/app.py", line 1478, in full_dispatch_request
    response = self.make_response(rv)
  File "/usr/local/lib/python2.7/site-packages/flask/app.py", line 1566, in make_response
    raise ValueError('View function did not return a response')
ValueError: View function did not return a response
[2016-02-11 23:50:20] ERROR    Exception on /tracker [GET]
Traceback (most recent call last):
  File "/usr/local/lib/python2.7/site-packages/flask/app.py", line 1817, in wsgi_app
    response = self.full_dispatch_request()
  File "/usr/local/lib/python2.7/site-packages/flask/app.py", line 1478, in full_dispatch_request
    response = self.make_response(rv)
  File "/usr/local/lib/python2.7/site-packages/flask/app.py", line 1566, in make_response
    raise ValueError('View function did not return a response')
ValueError: View function did not return a response
[2016-02-11 23:50:25] ERROR    Exception on /tracker [GET]
Traceback (most recent call last):
  File "/usr/local/lib/python2.7/site-packages/flask/app.py", line 1817, in wsgi_app
    response = self.full_dispatch_request()
  File "/usr/local/lib/python2.7/site-packages/flask/app.py", line 1478, in full_dispatch_request
    response = self.make_response(rv)
  File "/usr/local/lib/python2.7/site-packages/flask/app.py", line 1566, in make_response
    raise ValueError('View function did not return a response')
ValueError: View function did not return a response
[2016-02-11 23:50:29] ERROR    Exception on /tracker [GET]
Traceback (most recent call last):
  File "/usr/local/lib/python2.7/site-packages/flask/app.py", line 1817, in wsgi_app
    response = self.full_dispatch_request()
  File "/usr/local/lib/python2.7/site-packages/flask/app.py", line 1478, in full_dispatch_request
    response = self.make_response(rv)
  File "/usr/local/lib/python2.7/site-packages/flask/app.py", line 1566, in make_response
    raise ValueError('View function did not return a response')
ValueError: View function did not return a response
[2016-02-12 13:23:32] ERROR    Exception on /tracker [GET]
Traceback (most recent call last):
  File "/usr/local/lib/python2.7/site-packages/flask/app.py", line 1817, in wsgi_app
    response = self.full_dispatch_request()
  File "/usr/local/lib/python2.7/site-packages/flask/app.py", line 1478, in full_dispatch_request
    response = self.make_response(rv)
  File "/usr/local/lib/python2.7/site-packages/flask/app.py", line 1566, in make_response
    raise ValueError('View function did not return a response')
ValueError: View function did not return a response
[2016-02-12 15:39:01] ERROR    Exception on /tracker [GET]
Traceback (most recent call last):
  File "/usr/local/lib/python2.7/site-packages/flask/app.py", line 1817, in wsgi_app
    response = self.full_dispatch_request()
  File "/usr/local/lib/python2.7/site-packages/flask/app.py", line 1478, in full_dispatch_request
    response = self.make_response(rv)
  File "/usr/local/lib/python2.7/site-packages/flask/app.py", line 1566, in make_response
    raise ValueError('View function did not return a response')
ValueError: View function did not return a response
[2016-02-12 15:58:13] ERROR    Exception on /tracker [GET]
Traceback (most recent call last):
  File "/usr/local/lib/python2.7/site-packages/flask/app.py", line 1817, in wsgi_app
    response = self.full_dispatch_request()
  File "/usr/local/lib/python2.7/site-packages/flask/app.py", line 1478, in full_dispatch_request
    response = self.make_response(rv)
  File "/usr/local/lib/python2.7/site-packages/flask/app.py", line 1566, in make_response
    raise ValueError('View function did not return a response')
ValueError: View function did not return a response
[2016-02-12 17:35:58] ERROR    Exception on /submit_data [POST]
Traceback (most recent call last):
  File "/usr/local/lib/python2.7/site-packages/flask/app.py", line 1817, in wsgi_app
    response = self.full_dispatch_request()
  File "/usr/local/lib/python2.7/site-packages/flask/app.py", line 1478, in full_dispatch_request
    response = self.make_response(rv)
  File "/usr/local/lib/python2.7/site-packages/flask/app.py", line 1566, in make_response
    raise ValueError('View function did not return a response')
ValueError: View function did not return a response
[2016-02-12 18:26:55] ERROR    Exception on /submit_data [POST]
Traceback (most recent call last):
  File "/usr/local/lib/python2.7/site-packages/flask/app.py", line 1817, in wsgi_app
    response = self.full_dispatch_request()
  File "/usr/local/lib/python2.7/site-packages/flask/app.py", line 1477, in full_dispatch_request
    rv = self.handle_user_exception(e)
  File "/usr/local/lib/python2.7/site-packages/flask/app.py", line 1381, in handle_user_exception
    reraise(exc_type, exc_value, tb)
  File "/usr/local/lib/python2.7/site-packages/flask/app.py", line 1475, in full_dispatch_request
    rv = self.dispatch_request()
  File "/usr/local/lib/python2.7/site-packages/flask/app.py", line 1461, in dispatch_request
    return self.view_functions[rule.endpoint](**req.view_args)
  File "PCA_tester.py", line 539, in submit_data
    num_segments = inbound_data['segments'].strip("[]")
AttributeError: 'list' object has no attribute 'strip'
[2016-02-12 18:30:44] ERROR    Exception on /submit_data [POST]
Traceback (most recent call last):
  File "/usr/local/lib/python2.7/site-packages/flask/app.py", line 1817, in wsgi_app
    response = self.full_dispatch_request()
  File "/usr/local/lib/python2.7/site-packages/flask/app.py", line 1477, in full_dispatch_request
    rv = self.handle_user_exception(e)
  File "/usr/local/lib/python2.7/site-packages/flask/app.py", line 1381, in handle_user_exception
    reraise(exc_type, exc_value, tb)
  File "/usr/local/lib/python2.7/site-packages/flask/app.py", line 1475, in full_dispatch_request
    rv = self.dispatch_request()
  File "/usr/local/lib/python2.7/site-packages/flask/app.py", line 1461, in dispatch_request
    return self.view_functions[rule.endpoint](**req.view_args)
  File "PCA_tester.py", line 539, in submit_data
    num_segments = inbound_data['segments'].strip("[]")
AttributeError: 'list' object has no attribute 'strip'
[2016-02-12 18:33:42] ERROR    Exception on /submit_data [POST]
Traceback (most recent call last):
  File "/usr/local/lib/python2.7/site-packages/flask/app.py", line 1817, in wsgi_app
    response = self.full_dispatch_request()
  File "/usr/local/lib/python2.7/site-packages/flask/app.py", line 1477, in full_dispatch_request
    rv = self.handle_user_exception(e)
  File "/usr/local/lib/python2.7/site-packages/flask/app.py", line 1381, in handle_user_exception
    reraise(exc_type, exc_value, tb)
  File "/usr/local/lib/python2.7/site-packages/flask/app.py", line 1475, in full_dispatch_request
    rv = self.dispatch_request()
  File "/usr/local/lib/python2.7/site-packages/flask/app.py", line 1461, in dispatch_request
    return self.view_functions[rule.endpoint](**req.view_args)
  File "PCA_tester.py", line 539, in submit_data
    num_segments = int(inbound_data['segments'])
TypeError: int() argument must be a string or a number, not 'list'
[2016-02-12 18:38:49] ERROR    Exception on /submit_data [POST]
Traceback (most recent call last):
  File "/usr/local/lib/python2.7/site-packages/flask/app.py", line 1817, in wsgi_app
    response = self.full_dispatch_request()
  File "/usr/local/lib/python2.7/site-packages/flask/app.py", line 1477, in full_dispatch_request
    rv = self.handle_user_exception(e)
  File "/usr/local/lib/python2.7/site-packages/flask/app.py", line 1381, in handle_user_exception
    reraise(exc_type, exc_value, tb)
  File "/usr/local/lib/python2.7/site-packages/flask/app.py", line 1475, in full_dispatch_request
    rv = self.dispatch_request()
  File "/usr/local/lib/python2.7/site-packages/flask/app.py", line 1461, in dispatch_request
    return self.view_functions[rule.endpoint](**req.view_args)
  File "PCA_tester.py", line 547, in submit_data
    print "num_segments", len (num_segments), num_segments
TypeError: object of type 'int' has no len()
[2016-02-12 18:43:21] ERROR    Exception on /submit_data [POST]
Traceback (most recent call last):
  File "/usr/local/lib/python2.7/site-packages/flask/app.py", line 1817, in wsgi_app
    response = self.full_dispatch_request()
  File "/usr/local/lib/python2.7/site-packages/flask/app.py", line 1477, in full_dispatch_request
    rv = self.handle_user_exception(e)
  File "/usr/local/lib/python2.7/site-packages/flask/app.py", line 1381, in handle_user_exception
    reraise(exc_type, exc_value, tb)
  File "/usr/local/lib/python2.7/site-packages/flask/app.py", line 1475, in full_dispatch_request
    rv = self.dispatch_request()
  File "/usr/local/lib/python2.7/site-packages/flask/app.py", line 1461, in dispatch_request
    return self.view_functions[rule.endpoint](**req.view_args)
  File "PCA_tester.py", line 548, in submit_data
    print "num_segments:", len(num_segments), num_segments
TypeError: object of type 'int' has no len()
[2016-02-12 18:49:46] ERROR    Exception on /submit_data [POST]
Traceback (most recent call last):
  File "/usr/local/lib/python2.7/site-packages/flask/app.py", line 1817, in wsgi_app
    response = self.full_dispatch_request()
  File "/usr/local/lib/python2.7/site-packages/flask/app.py", line 1477, in full_dispatch_request
    rv = self.handle_user_exception(e)
  File "/usr/local/lib/python2.7/site-packages/flask/app.py", line 1381, in handle_user_exception
    reraise(exc_type, exc_value, tb)
  File "/usr/local/lib/python2.7/site-packages/flask/app.py", line 1475, in full_dispatch_request
    rv = self.dispatch_request()
  File "/usr/local/lib/python2.7/site-packages/flask/app.py", line 1461, in dispatch_request
    return self.view_functions[rule.endpoint](**req.view_args)
  File "PCA_tester.py", line 549, in submit_data
    print "num_segments:", len(num_segments), num_segments
TypeError: object of type 'int' has no len()
[2016-02-12 18:53:05] ERROR    Exception on /submit_data [POST]
Traceback (most recent call last):
  File "/usr/local/lib/python2.7/site-packages/flask/app.py", line 1817, in wsgi_app
    response = self.full_dispatch_request()
  File "/usr/local/lib/python2.7/site-packages/flask/app.py", line 1477, in full_dispatch_request
    rv = self.handle_user_exception(e)
  File "/usr/local/lib/python2.7/site-packages/flask/app.py", line 1381, in handle_user_exception
    reraise(exc_type, exc_value, tb)
  File "/usr/local/lib/python2.7/site-packages/flask/app.py", line 1475, in full_dispatch_request
    rv = self.dispatch_request()
  File "/usr/local/lib/python2.7/site-packages/flask/app.py", line 1461, in dispatch_request
    return self.view_functions[rule.endpoint](**req.view_args)
  File "PCA_tester.py", line 551, in submit_data
    print "num_segments:", len(num_segments), num_segments
TypeError: object of type 'int' has no len()
[2016-02-12 19:02:03] ERROR    Exception on /submit_data [POST]
Traceback (most recent call last):
  File "/usr/local/lib/python2.7/site-packages/flask/app.py", line 1817, in wsgi_app
    response = self.full_dispatch_request()
  File "/usr/local/lib/python2.7/site-packages/flask/app.py", line 1477, in full_dispatch_request
    rv = self.handle_user_exception(e)
  File "/usr/local/lib/python2.7/site-packages/flask/app.py", line 1381, in handle_user_exception
    reraise(exc_type, exc_value, tb)
  File "/usr/local/lib/python2.7/site-packages/flask/app.py", line 1475, in full_dispatch_request
    rv = self.dispatch_request()
  File "/usr/local/lib/python2.7/site-packages/flask/app.py", line 1461, in dispatch_request
    return self.view_functions[rule.endpoint](**req.view_args)
  File "PCA_tester.py", line 536, in submit_data
    questions = inbound_data['questions'].strip("[]").split(',').encode('ascii', 'ignore')
AttributeError: 'list' object has no attribute 'encode'
[2016-02-12 19:16:43] ERROR    Exception on /submit_data [POST]
Traceback (most recent call last):
  File "/usr/local/lib/python2.7/site-packages/flask/app.py", line 1817, in wsgi_app
    response = self.full_dispatch_request()
  File "/usr/local/lib/python2.7/site-packages/flask/app.py", line 1477, in full_dispatch_request
    rv = self.handle_user_exception(e)
  File "/usr/local/lib/python2.7/site-packages/flask/app.py", line 1381, in handle_user_exception
    reraise(exc_type, exc_value, tb)
  File "/usr/local/lib/python2.7/site-packages/flask/app.py", line 1475, in full_dispatch_request
    rv = self.dispatch_request()
  File "/usr/local/lib/python2.7/site-packages/flask/app.py", line 1461, in dispatch_request
    return self.view_functions[rule.endpoint](**req.view_args)
  File "PCA_tester.py", line 553, in submit_data
    results = run_poLCA (grid_search,cluster_seed,num_seg,num_rep,rebucketed_filename)
  File "PCA_tester.py", line 901, in run_poLCA
    timestamp, cluster_seeds, cluster_seed_names, num_seg = poLCA (1, cluster_seed,num_seg,num_rep,rebucketed_filename)
  File "PCA_tester.py", line 368, in poLCA
    cluster_seed_names = [names[int(value)] for value in cluster_seed]
ValueError: invalid literal for int() with base 10: 'q39_8'
[2016-02-12 19:19:28] ERROR    Exception on /submit_data [POST]
Traceback (most recent call last):
  File "/usr/local/lib/python2.7/site-packages/flask/app.py", line 1817, in wsgi_app
    response = self.full_dispatch_request()
  File "/usr/local/lib/python2.7/site-packages/flask/app.py", line 1477, in full_dispatch_request
    rv = self.handle_user_exception(e)
  File "/usr/local/lib/python2.7/site-packages/flask/app.py", line 1381, in handle_user_exception
    reraise(exc_type, exc_value, tb)
  File "/usr/local/lib/python2.7/site-packages/flask/app.py", line 1475, in full_dispatch_request
    rv = self.dispatch_request()
  File "/usr/local/lib/python2.7/site-packages/flask/app.py", line 1461, in dispatch_request
    return self.view_functions[rule.endpoint](**req.view_args)
  File "PCA_tester.py", line 553, in submit_data
    results = run_poLCA (grid_search,cluster_seed,num_seg,num_rep,rebucketed_filename)
  File "PCA_tester.py", line 901, in run_poLCA
    timestamp, cluster_seeds, cluster_seed_names, num_seg = poLCA (1, cluster_seed,num_seg,num_rep,rebucketed_filename)
  File "PCA_tester.py", line 368, in poLCA
    cluster_seed_names = [names[int(value)] for value in cluster_seed]
ValueError: invalid literal for int() with base 10: 'q39_8'
[2016-02-12 19:23:59] ERROR    Exception on /submit_data [POST]
Traceback (most recent call last):
  File "/usr/local/lib/python2.7/site-packages/flask/app.py", line 1817, in wsgi_app
    response = self.full_dispatch_request()
  File "/usr/local/lib/python2.7/site-packages/flask/app.py", line 1477, in full_dispatch_request
    rv = self.handle_user_exception(e)
  File "/usr/local/lib/python2.7/site-packages/flask/app.py", line 1381, in handle_user_exception
    reraise(exc_type, exc_value, tb)
  File "/usr/local/lib/python2.7/site-packages/flask/app.py", line 1475, in full_dispatch_request
    rv = self.dispatch_request()
  File "/usr/local/lib/python2.7/site-packages/flask/app.py", line 1461, in dispatch_request
    return self.view_functions[rule.endpoint](**req.view_args)
  File "PCA_tester.py", line 555, in submit_data
    results = run_poLCA (grid_search,cluster_seed,num_seg,num_rep,rebucketed_filename)
  File "PCA_tester.py", line 903, in run_poLCA
    timestamp, cluster_seeds, cluster_seed_names, num_seg = poLCA (1, cluster_seed,num_seg,num_rep,rebucketed_filename)
  File "PCA_tester.py", line 369, in poLCA
    cluster_seed_names = [names[int(value)] for value in cluster_seed]
ValueError: invalid literal for int() with base 10: 'q39_8'
[2016-02-12 19:41:23] ERROR    Exception on /submit_data [POST]
Traceback (most recent call last):
  File "/usr/local/lib/python2.7/site-packages/flask/app.py", line 1817, in wsgi_app
    response = self.full_dispatch_request()
  File "/usr/local/lib/python2.7/site-packages/flask/app.py", line 1477, in full_dispatch_request
    rv = self.handle_user_exception(e)
  File "/usr/local/lib/python2.7/site-packages/flask/app.py", line 1381, in handle_user_exception
    reraise(exc_type, exc_value, tb)
  File "/usr/local/lib/python2.7/site-packages/flask/app.py", line 1475, in full_dispatch_request
    rv = self.dispatch_request()
  File "/usr/local/lib/python2.7/site-packages/flask/app.py", line 1461, in dispatch_request
    return self.view_functions[rule.endpoint](**req.view_args)
  File "PCA_tester.py", line 559, in submit_data
    print "----run number:", len(results_dict.keys()), "-----------"
UnboundLocalError: local variable 'results_dict' referenced before assignment
[2016-02-12 19:44:08] ERROR    Exception on /submit_data [POST]
Traceback (most recent call last):
  File "/usr/local/lib/python2.7/site-packages/flask/app.py", line 1817, in wsgi_app
    response = self.full_dispatch_request()
  File "/usr/local/lib/python2.7/site-packages/flask/app.py", line 1477, in full_dispatch_request
    rv = self.handle_user_exception(e)
  File "/usr/local/lib/python2.7/site-packages/flask/app.py", line 1381, in handle_user_exception
    reraise(exc_type, exc_value, tb)
  File "/usr/local/lib/python2.7/site-packages/flask/app.py", line 1475, in full_dispatch_request
    rv = self.dispatch_request()
  File "/usr/local/lib/python2.7/site-packages/flask/app.py", line 1461, in dispatch_request
    return self.view_functions[rule.endpoint](**req.view_args)
  File "PCA_tester.py", line 563, in submit_data
    question_dict, results_dict = update_question_dict(question_dict,results_dict)
UnboundLocalError: local variable 'question_dict' referenced before assignment
[2016-02-12 19:49:09] ERROR    Exception on /submit_data [POST]
Traceback (most recent call last):
  File "/usr/local/lib/python2.7/site-packages/flask/app.py", line 1817, in wsgi_app
    response = self.full_dispatch_request()
  File "/usr/local/lib/python2.7/site-packages/flask/app.py", line 1477, in full_dispatch_request
    rv = self.handle_user_exception(e)
  File "/usr/local/lib/python2.7/site-packages/flask/app.py", line 1381, in handle_user_exception
    reraise(exc_type, exc_value, tb)
  File "/usr/local/lib/python2.7/site-packages/flask/app.py", line 1475, in full_dispatch_request
    rv = self.dispatch_request()
  File "/usr/local/lib/python2.7/site-packages/flask/app.py", line 1461, in dispatch_request
    return self.view_functions[rule.endpoint](**req.view_args)
  File "PCA_tester.py", line 566, in submit_data
    question_dict, results_dict = update_question_dict(question_dict,results_dict)
UnboundLocalError: local variable 'question_dict' referenced before assignment
[2016-02-12 19:54:07] ERROR    Exception on /submit_data [POST]
Traceback (most recent call last):
  File "/usr/local/lib/python2.7/site-packages/flask/app.py", line 1817, in wsgi_app
    response = self.full_dispatch_request()
  File "/usr/local/lib/python2.7/site-packages/flask/app.py", line 1477, in full_dispatch_request
    rv = self.handle_user_exception(e)
  File "/usr/local/lib/python2.7/site-packages/flask/app.py", line 1381, in handle_user_exception
    reraise(exc_type, exc_value, tb)
  File "/usr/local/lib/python2.7/site-packages/flask/app.py", line 1475, in full_dispatch_request
    rv = self.dispatch_request()
  File "/usr/local/lib/python2.7/site-packages/flask/app.py", line 1461, in dispatch_request
    return self.view_functions[rule.endpoint](**req.view_args)
  File "PCA_tester.py", line 567, in submit_data
    print "question_dict:", len(question_dict)
UnboundLocalError: local variable 'question_dict' referenced before assignment
[2016-02-12 19:55:31] ERROR    Exception on /submit_data [POST]
Traceback (most recent call last):
  File "/usr/local/lib/python2.7/site-packages/flask/app.py", line 1817, in wsgi_app
    response = self.full_dispatch_request()
  File "/usr/local/lib/python2.7/site-packages/flask/app.py", line 1477, in full_dispatch_request
    rv = self.handle_user_exception(e)
  File "/usr/local/lib/python2.7/site-packages/flask/app.py", line 1381, in handle_user_exception
    reraise(exc_type, exc_value, tb)
  File "/usr/local/lib/python2.7/site-packages/flask/app.py", line 1475, in full_dispatch_request
    rv = self.dispatch_request()
  File "/usr/local/lib/python2.7/site-packages/flask/app.py", line 1461, in dispatch_request
    return self.view_functions[rule.endpoint](**req.view_args)
  File "PCA_tester.py", line 567, in submit_data
    print "question_dict:", len(question_dict)
UnboundLocalError: local variable 'question_dict' referenced before assignment
[2016-02-12 19:56:47] ERROR    Exception on /submit_data [POST]
Traceback (most recent call last):
  File "/usr/local/lib/python2.7/site-packages/flask/app.py", line 1817, in wsgi_app
    response = self.full_dispatch_request()
  File "/usr/local/lib/python2.7/site-packages/flask/app.py", line 1477, in full_dispatch_request
    rv = self.handle_user_exception(e)
  File "/usr/local/lib/python2.7/site-packages/flask/app.py", line 1381, in handle_user_exception
    reraise(exc_type, exc_value, tb)
  File "/usr/local/lib/python2.7/site-packages/flask/app.py", line 1475, in full_dispatch_request
    rv = self.dispatch_request()
  File "/usr/local/lib/python2.7/site-packages/flask/app.py", line 1461, in dispatch_request
    return self.view_functions[rule.endpoint](**req.view_args)
  File "PCA_tester.py", line 567, in submit_data
    print "question_dict:", len(question_dict)
UnboundLocalError: local variable 'question_dict' referenced before assignment
[2016-02-12 20:00:17] ERROR    Exception on /submit_data [POST]
Traceback (most recent call last):
  File "/usr/local/lib/python2.7/site-packages/flask/app.py", line 1817, in wsgi_app
    response = self.full_dispatch_request()
  File "/usr/local/lib/python2.7/site-packages/flask/app.py", line 1477, in full_dispatch_request
    rv = self.handle_user_exception(e)
  File "/usr/local/lib/python2.7/site-packages/flask/app.py", line 1381, in handle_user_exception
    reraise(exc_type, exc_value, tb)
  File "/usr/local/lib/python2.7/site-packages/flask/app.py", line 1475, in full_dispatch_request
    rv = self.dispatch_request()
  File "/usr/local/lib/python2.7/site-packages/flask/app.py", line 1461, in dispatch_request
    return self.view_functions[rule.endpoint](**req.view_args)
  File "PCA_tester.py", line 567, in submit_data
    print "---question_dict:-----", len(question_dict)
UnboundLocalError: local variable 'question_dict' referenced before assignment
[2016-02-12 20:02:26] ERROR    Exception on /submit_data [POST]
Traceback (most recent call last):
  File "/usr/local/lib/python2.7/site-packages/flask/app.py", line 1817, in wsgi_app
    response = self.full_dispatch_request()
  File "/usr/local/lib/python2.7/site-packages/flask/app.py", line 1477, in full_dispatch_request
    rv = self.handle_user_exception(e)
  File "/usr/local/lib/python2.7/site-packages/flask/app.py", line 1381, in handle_user_exception
    reraise(exc_type, exc_value, tb)
  File "/usr/local/lib/python2.7/site-packages/flask/app.py", line 1475, in full_dispatch_request
    rv = self.dispatch_request()
  File "/usr/local/lib/python2.7/site-packages/flask/app.py", line 1461, in dispatch_request
    return self.view_functions[rule.endpoint](**req.view_args)
  File "PCA_tester.py", line 567, in submit_data
    print "---question_dict:-----", len(question_dict)
UnboundLocalError: local variable 'question_dict' referenced before assignment
[2016-02-12 23:32:10] ERROR    Exception on /submit_data [POST]
Traceback (most recent call last):
  File "/usr/local/lib/python2.7/site-packages/flask/app.py", line 1817, in wsgi_app
    response = self.full_dispatch_request()
  File "/usr/local/lib/python2.7/site-packages/flask/app.py", line 1477, in full_dispatch_request
    rv = self.handle_user_exception(e)
  File "/usr/local/lib/python2.7/site-packages/flask/app.py", line 1381, in handle_user_exception
    reraise(exc_type, exc_value, tb)
  File "/usr/local/lib/python2.7/site-packages/flask/app.py", line 1475, in full_dispatch_request
    rv = self.dispatch_request()
  File "/usr/local/lib/python2.7/site-packages/flask/app.py", line 1461, in dispatch_request
    return self.view_functions[rule.endpoint](**req.view_args)
  File "PCA_tester.py", line 573, in submit_data
    timestamps = make_results_dict(results, X_rebucketed, names)
  File "PCA_tester.py", line 700, in make_results_dict
    results_dict[key]['cluster_number'] = cluster_numbers[num]
IndexError: list index out of range
[2016-02-13 00:19:00] ERROR    Exception on /submit_data [POST]
Traceback (most recent call last):
  File "/usr/local/lib/python2.7/site-packages/flask/app.py", line 1817, in wsgi_app
    response = self.full_dispatch_request()
  File "/usr/local/lib/python2.7/site-packages/flask/app.py", line 1477, in full_dispatch_request
    rv = self.handle_user_exception(e)
  File "/usr/local/lib/python2.7/site-packages/flask/app.py", line 1381, in handle_user_exception
    reraise(exc_type, exc_value, tb)
  File "/usr/local/lib/python2.7/site-packages/flask/app.py", line 1475, in full_dispatch_request
    rv = self.dispatch_request()
  File "/usr/local/lib/python2.7/site-packages/flask/app.py", line 1461, in dispatch_request
    return self.view_functions[rule.endpoint](**req.view_args)
  File "PCA_tester.py", line 572, in submit_data
    results = run_poLCA (grid_search,cluster_seed,num_seg,num_rep,rebucketed_filename)
  File "PCA_tester.py", line 965, in run_poLCA
    scorecard(timestamp, cluster_seeds, cluster_seed_names, num_seg)
  File "PCA_tester.py", line 651, in scorecard
    print "Run number:", results_dict[timestamp]['run_number']
KeyError: '7cd61de2-4530-4506-b4a2-9673ff2a455d'
[2016-02-19 13:56:33] INFO     FileName: X_rebucketed.csv
[2016-02-19 14:02:54] INFO     FileName: X_rebucketed.csv
[2016-02-19 14:11:55] INFO     FileName: clustering_data_export.xlsx
[2016-02-19 14:15:27] INFO     FileName: test_raw_data_v1.csv
[2016-02-19 14:23:24] INFO     FileName: test_raw_data_v1.csv
[2016-02-19 14:38:19] INFO     FileName: test_raw_data_v1.csv
[2016-02-19 14:38:32] INFO     FileName: test_raw_data_v1.csv
[2016-02-19 14:42:35] INFO     FileName: test_raw_data_v1_copy.csv
[2016-02-19 14:50:30] INFO     FileName: test_raw_data_v1_zq_copy.csv
[2016-02-19 14:58:58] INFO     FileName: test_raw_data_v1_copy.csv
[2016-02-19 15:01:15] INFO     FileName: test_raw_data_v1_zq_copy.csv
[2016-02-19 15:47:41] INFO     FileName: test_raw_data_v1_copy.csv
[2016-02-19 15:50:24] INFO     FileName: test_raw_data_v1_copy.csv
[2016-02-19 15:52:49] INFO     FileName: test_raw_data_v1_zq_copy.csv
[2016-02-19 16:02:01] INFO     FileName: test_raw_data_v1_copy.csv
[2016-02-19 16:03:33] INFO     FileName: test_raw_data_v1_zq_copy.csv
[2016-02-19 16:08:06] INFO     FileName: test_raw_data_v1_copy.csv
[2016-02-19 16:09:09] INFO     FileName: test_raw_data_v1_zq_copy.csv
[2016-02-19 16:11:16] INFO     FileName: test_raw_data_v1_zq_copy.csv
[2016-02-19 16:15:36] INFO     FileName: test_raw_data_v1_zq_copy.csv
[2016-02-19 16:17:19] INFO     FileName: test_raw_data_v1_copy.csv
[2016-02-19 16:23:35] INFO     FileName: test_raw_data_v1_zq_copy.csv
[2016-02-19 16:27:15] INFO     FileName: test_raw_data_v1_zq_copy.csv
[2016-02-19 19:26:17] INFO     FileName: test_raw_data_v1_copy.csv
[2016-02-20 18:47:55] INFO     FileName: test_raw_data_v1_zq_copy.csv
[2016-02-21 18:16:13] INFO     FileName: test_raw_data_v1.csv
[2016-02-21 18:26:10] INFO     FileName: test_raw_data_v1_zq_copy.csv
[2016-02-21 18:28:44] INFO     FileName: test_raw_data_v1_copy.csv
[2016-02-21 18:39:37] INFO     FileName: test_raw_data_v1_zq_copy.csv
[2016-02-21 18:40:44] INFO     FileName: test_raw_data_v1_copy.csv
[2016-02-21 20:07:20] INFO     FileName: test_raw_data_v1_zq_copy.csv
